Workbook

Sheet Spis tablic List of tables
B2: PROGNOZA LUDNOŚCI NA LATA 2023-2060
B3: POPULATION PROJECTION 2023-2060
B5: Scenariusz wysoki
B6: High scenario
B8: Spis tablic
B9: List of tables
B12: TABL. 1. | D12: LUDNOŚĆ WEDŁUG PŁCI I POJEDYNCZYCH ROCZNIKÓW WIEKU
D13: POPULATION BY SEX AND SINGLE YEAR OF AGE
B15: TABL. 2. | D15: LUDNOŚĆ WEDŁUG PŁCI I PIĘCIOLETNICH GRUP WIEKU
D16: POPULATION BY SEX AND 5-YEAR AGE GROUPS
B18: TABL. 3. | D18: LUDNOŚĆ WEDŁUG PŁCI I WYBRANYCH GRUP WIEKU
D19: POPULATION BY SEX AND SELECTED GROUPS OF AGE
B21: TABL. 4. | D21: RUCH NATURALNY I MIGRACYJNY LUDNOŚCI
D22: VITAL STATISTICS
B24: WYKRES 1. | D24: PIRAMIDA LUDNOŚCI
B25: CHART 1. | D25: POPULATION PYRAMID

Sheet Tabl. 1
C1: TABL. 1. LUDNOŚĆ WEDŁUG PŁCI I POJEDYNCZYCH ROCZNIKÓW WIEKU
A2: Powrót do spisu tablic | D2: Stan w dniu 31 XII
A3: Return to the list of tables | D3: POPULATION BY SEX AND SINGLE YEAR OF AGE
D4: As of 31 XII
D5: * dane empiryczne empirical data
A6: małopolskie
A7: Płeć Sex | B7: Wiek Age | C7: 2022* | D7: 2023 | E7: 2024 | F7: 2025 | G7: 2026 | H7: 2027 | I7: 2028 | J7: 2029 | K7: 2030 | L7: 2031 | M7: 2032 | N7: 2033 | O7: 2034 | P7: 2035 | Q7: 2036 | R7: 2037 | S7: 2038 | T7: 2039 | U7: 2040 | V7: 2041 | W7: 2042 | X7: 2043 | Y7: 2044 | Z7: 2045 | AA7: 2046 | AB7: 2047 | AC7: 2048 | AD7: 2049 | AE7: 2050 | AF7: 2051 | AG7: 2052 | AH7: 2053 | AI7: 2054 | AJ7: 2055 | AK7: 2056 | AL7: 2057 | AM7: 2058 | AN7: 2059 | AO7: 2060
A8: Ogółem Total | B8: Ogółem Total | C8: 3429014 | D8: 3430361 | E8: 3432698 | F8: 3435619 | G8: 3439093 | H8: 3456350 | I8: 3478788 | J8: 3490538 | K8: 3496654 | L8: 3500645 | M8: 3503222 | N8: 3504826 | O8: 3505452 | P8: 3505638 | Q8: 3505601 | R8: 3505303 | S8: 3504832 | T8: 3504305 | U8: 3503693 | V8: 3503292 | W8: 3502945 | X8: 3502554 | Y8: 3502396 | Z8: 3501931 | AA8: 3501425 | AB8: 3501031 | AC8: 3500425 | AD8: 3499641 | AE8: 3498662 | AF8: 3497419 | AG8: 3495862 | AH8: 3494207 | AI8: 3492184 | AJ8: 3490127 | AK8: 3487547 | AL8: 3484688 | AM8: 3481818 | AN8: 3478783 | AO8: 3475560
B9: 0 | C9: 30661 | D9: 32193 | E9: 32754 | F9: 33157 | G9: 33422 | H9: 33649 | I9: 33918 | J9: 34088 | K9: 34045 | L9: 33939 | M9: 33713 | N9: 33460 | O9: 33222 | P9: 33068 | Q9: 33011 | R9: 33073 | S9: 33206 | T9: 33457 | U9: 33727 | V9: 34046 | W9: 34350 | X9: 34624 | Y9: 34872 | Z9: 35056 | AA9: 35192 | AB9: 35268 | AC9: 35277 | AD9: 35245 | AE9: 35107 | AF9: 34969 | AG9: 34778 | AH9: 34542 | AI9: 34301 | AJ9: 34089 | AK9: 33883 | AL9: 33700 | AM9: 33555 | AN9: 33484 | AO9: 33423
B10: 1 | C10: 33694 | D10: 30873 | E10: 32423 | F10: 32994 | G10: 33419 | H10: 33904 | I10: 34221 | J10: 34347 | K10: 34440 | L10: 34390 | M10: 34281 | N10: 34057 | O10: 33804 | P10: 33578 | Q10: 33434 | R10: 33392 | S10: 33465 | T10: 33605 | U10: 33866 | V10: 34139 | W10: 34458 | X10: 34761 | Y10: 35038 | Z10: 35288 | AA10: 35471 | AB10: 35605 | AC10: 35679 | AD10: 35688 | AE10: 35651 | AF10: 35514 | AG10: 35379 | AH10: 35192 | AI10: 34952 | AJ10: 34710 | AK10: 34500 | AL10: 34296 | AM10: 34115 | AN10: 33974 | AO10: 33906
B11: 2 | C11: 35106 | D11: 33876 | E11: 31066 | F11: 32638 | G11: 33225 | H11: 33960 | I11: 34565 | J11: 34658 | K11: 34679 | L11: 34748 | M11: 34688 | N11: 34577 | O11: 34354 | P11: 34107 | Q11: 33889 | R11: 33751 | S11: 33716 | T11: 33799 | U11: 33944 | V11: 34208 | W11: 34487 | X11: 34808 | Y11: 35108 | Z11: 35390 | AA11: 35638 | AB11: 35821 | AC11: 35960 | AD11: 36036 | AE11: 36046 | AF11: 36012 | AG11: 35873 | AH11: 35741 | AI11: 35551 | AJ11: 35308 | AK11: 35064 | AL11: 34854 | AM11: 34651 | AN11: 34470 | AO11: 34331
B12: 3 | C12: 37416 | D12: 35301 | E12: 34088 | F12: 31284 | G12: 32865 | H12: 33765 | I12: 34636 | J12: 35011 | K12: 34986 | L12: 34976 | M12: 35037 | N12: 34967 | O12: 34856 | P12: 34639 | Q12: 34401 | R12: 34196 | S12: 34066 | T12: 34035 | U12: 34122 | V12: 34272 | W12: 34542 | X12: 34825 | Y12: 35150 | Z12: 35449 | AA12: 35737 | AB12: 35985 | AC12: 36173 | AD12: 36313 | AE12: 36393 | AF12: 36400 | AG12: 36363 | AH12: 36223 | AI12: 36087 | AJ12: 35896 | AK12: 35655 | AL12: 35410 | AM12: 35195 | AN12: 34993 | AO12: 34812
B13: 4 | C13: 38746 | D13: 37588 | E13: 35497 | F13: 34300 | G13: 31506 | H13: 33396 | I13: 34410 | J13: 35068 | K13: 35328 | L13: 35259 | M13: 35231 | N13: 35286 | O13: 35218 | P13: 35117 | Q13: 34903 | R13: 34671 | S13: 34472 | T13: 34351 | U13: 34326 | V13: 34419 | W13: 34571 | X13: 34841 | Y13: 35123 | Z13: 35450 | AA13: 35758 | AB13: 36047 | AC13: 36292 | AD13: 36482 | AE13: 36619 | AF13: 36703 | AG13: 36708 | AH13: 36672 | AI13: 36529 | AJ13: 36392 | AK13: 36203 | AL13: 35966 | AM13: 35724 | AN13: 35512 | AO13: 35302
B14: 5 | C14: 39561 | D14: 38909 | E14: 37757 | F14: 35681 | G14: 34485 | H14: 32028 | I14: 34039 | J14: 34795 | K14: 35335 | L14: 35560 | M14: 35470 | N14: 35429 | O14: 35478 | P14: 35419 | Q14: 35325 | R14: 35115 | S14: 34890 | T14: 34696 | U14: 34579 | V14: 34560 | W14: 34662 | X14: 34817 | Y14: 35088 | Z14: 35378 | AA14: 35704 | AB14: 36012 | AC14: 36307 | AD14: 36551 | AE14: 36741 | AF14: 36879 | AG14: 36961 | AH14: 36963 | AI14: 36932 | AJ14: 36784 | AK14: 36641 | AL14: 36448 | AM14: 36217 | AN14: 35971 | AO14: 35755
B15: 6 | C15: 38340 | D15: 39697 | E15: 39042 | F15: 37905 | G15: 35845 | H15: 34993 | I15: 32667 | J15: 34418 | K15: 35043 | L15: 35540 | M15: 35739 | N15: 35636 | O15: 35596 | P15: 35647 | Q15: 35591 | R15: 35503 | S15: 35296 | T15: 35078 | U15: 34889 | V15: 34777 | W15: 34759 | X15: 34860 | Y15: 35021 | Z15: 35289 | AA15: 35582 | AB15: 35910 | AC15: 36219 | AD15: 36513 | AE15: 36760 | AF15: 36948 | AG15: 37082 | AH15: 37164 | AI15: 37163 | AJ15: 37131 | AK15: 36981 | AL15: 36841 | AM15: 36651 | AN15: 36418 | AO15: 36174
B16: 7 | C16: 37251 | D16: 38440 | E16: 39810 | F16: 39156 | G16: 38034 | H16: 36335 | I16: 35622 | J16: 33012 | K16: 34625 | L16: 35204 | M16: 35675 | N16: 35856 | O16: 35752 | P16: 35711 | Q16: 35767 | R16: 35714 | S16: 35634 | T16: 35430 | U16: 35217 | V16: 35030 | W16: 34921 | X16: 34905 | Y16: 35012 | Z16: 35173 | AA16: 35442 | AB16: 35735 | AC16: 36060 | AD16: 36368 | AE16: 36658 | AF16: 36910 | AG16: 37097 | AH16: 37230 | AI16: 37308 | AJ16: 37307 | AK16: 37272 | AL16: 37122 | AM16: 36983 | AN16: 36792 | AO16: 36560
B17: 8 | C17: 36911 | D17: 37317 | E17: 38506 | F17: 39887 | G17: 39236 | H17: 38504 | I17: 36958 | J17: 35937 | K17: 33189 | L17: 34742 | M17: 35300 | N17: 35751 | O17: 35922 | P17: 35820 | Q17: 35782 | R17: 35840 | S17: 35791 | T17: 35714 | U17: 35508 | V17: 35298 | W17: 35116 | X17: 35009 | Y17: 34998 | Z17: 35107 | AA17: 35268 | AB17: 35544 | AC17: 35835 | AD17: 36160 | AE17: 36469 | AF17: 36759 | AG17: 37010 | AH17: 37198 | AI17: 37325 | AJ17: 37405 | AK17: 37407 | AL17: 37370 | AM17: 37219 | AN17: 37079 | AO17: 36890
B18: 9 | C18: 36551 | D18: 36945 | E18: 37348 | F18: 38547 | G18: 39943 | H18: 39684 | I18: 39095 | J18: 37255 | K18: 36079 | L18: 33281 | M18: 34805 | N18: 35345 | O18: 35788 | P18: 35956 | Q18: 35858 | R18: 35825 | S18: 35882 | T18: 35833 | U18: 35758 | V18: 35555 | W18: 35347 | X18: 35169 | Y18: 35065 | Z18: 35058 | AA18: 35167 | AB18: 35326 | AC18: 35599 | AD18: 35893 | AE18: 36217 | AF18: 36526 | AG18: 36815 | AH18: 37065 | AI18: 37251 | AJ18: 37376 | AK18: 37455 | AL18: 37457 | AM18: 37423 | AN18: 37269 | AO18: 37128
B19: 10 | C19: 37840 | D19: 36569 | E19: 36967 | F19: 37375 | G19: 38587 | H19: 40389 | I19: 40275 | J19: 39387 | K19: 37389 | L19: 36156 | M19: 33327 | N19: 34824 | O19: 35355 | P19: 35799 | Q19: 35968 | R19: 35871 | S19: 35839 | T19: 35897 | U19: 35848 | V19: 35775 | W19: 35576 | X19: 35371 | Y19: 35193 | Z19: 35093 | AA19: 35089 | AB19: 35199 | AC19: 35359 | AD19: 35636 | AE19: 35932 | AF19: 36254 | AG19: 36563 | AH19: 36849 | AI19: 37096 | AJ19: 37280 | AK19: 37405 | AL19: 37483 | AM19: 37483 | AN19: 37448 | AO19: 37296
B20: 11 | C20: 37963 | D20: 37854 | E20: 36586 | F20: 36993 | G20: 37406 | H20: 39001 | I20: 40949 | J20: 40531 | K20: 39501 | L20: 37451 | M20: 36185 | N20: 33343 | O20: 34831 | P20: 35361 | Q20: 35806 | R20: 35974 | S20: 35876 | T20: 35846 | U20: 35904 | V20: 35856 | W20: 35784 | X20: 35587 | Y20: 35384 | Z20: 35208 | AA20: 35106 | AB20: 35104 | AC20: 35215 | AD20: 35373 | AE20: 35649 | AF20: 35950 | AG20: 36276 | AH20: 36585 | AI20: 36869 | AJ20: 37116 | AK20: 37299 | AL20: 37421 | AM20: 37498 | AN20: 37497 | AO20: 37460
... B108: 99 | C108: 339 | D108: 320 | E108: 403 | F108: 433 | G108: 452 | H108: 534 | I108: 599 | J108: 713 | K108: 757 | L108: 829 | M108: 824 | N108: 858 | O108: 951 | P108: 1023 | Q108: 1040 | R108: 1073 | S108: 1138 | T108: 1139 | U108: 1034 | V108: 1002 | W108: 1151 | X108: 1294 | Y108: 1343 | Z108: 1621 | AA108: 1883 | AB108: 2059 | AC108: 2183 | AD108: 2342 | AE108: 2559 | AF108: 2695 | AG108: 2818 | AH108: 2942 | AI108: 3171 | AJ108: 3234 | AK108: 3389 | AL108: 3516 | AM108: 3535 | AN108: 3551 | AO108: 3482
B109: 100+ | C109: 472 | D109: 536 | E109: 571 | F109: 653 | G109: 738 | H109: 809 | I109: 924 | J109: 1049 | K109: 1219 | L109: 1371 | M109: 1533 | N109: 1647 | O109: 1757 | P109: 1903 | Q109: 2071 | R109: 2202 | S109: 2325 | T109: 2465 | U109: 2566 | V109: 2582 | W109: 2581 | X109: 2692 | Y109: 2899 | Z109: 3082 | AA109: 3432 | AB109: 3894 | AC109: 4376 | AD109: 4831 | AE109: 5300 | AF109: 5821 | AG109: 6322 | AH109: 6805 | AI109: 7271 | AJ109: 7829 | AK109: 8306 | AL109: 8796 | AM109: 9288 | AN109: 9702 | AO109: 10041
A110: Mężczyźni Males | B110: Ogółem Total | C110: 1663091 | D110: 1663512 | E110: 1664426 | F110: 1665597 | G110: 1666951 | H110: 1673185 | I110: 1681118 | J110: 1685428 | K110: 1687817 | L110: 1689399 | M110: 1690460 | N110: 1691106 | O110: 1691275 | P110: 1691340 | Q110: 1691278 | R110: 1691183 | S110: 1691121 | T110: 1690912 | U110: 1690756 | V110: 1690717 | W110: 1690804 | X110: 1690978 | Y110: 1691277 | Z110: 1691452 | AA110: 1691721 | AB110: 1692027 | AC110: 1692363 | AD110: 1692641 | AE110: 1692680 | AF110: 1692670 | AG110: 1692602 | AH110: 1692438 | AI110: 1692128 | AJ110: 1691776 | AK110: 1691112 | AL110: 1690362 | AM110: 1689582 | AN110: 1688769 | AO110: 1687951
B111: 0 | C111: 15728 | D111: 16567 | E111: 16860 | F111: 17066 | G111: 17201 | H111: 17320 | I111: 17456 | J111: 17542 | K111: 17523 | L111: 17471 | M111: 17355 | N111: 17225 | O111: 17103 | P111: 17026 | Q111: 16995 | R111: 17025 | S111: 17094 | T111: 17224 | U111: 17364 | V111: 17525 | W111: 17682 | X111: 17821 | Y111: 17948 | Z111: 18044 | AA111: 18119 | AB111: 18154 | AC111: 18161 | AD111: 18144 | AE111: 18074 | AF111: 18002 | AG111: 17905 | AH111: 17782 | AI111: 17664 | AJ111: 17549 | AK111: 17446 | AL111: 17350 | AM111: 17275 | AN111: 17239 | AO111: 17206
B112: 1 | C112: 17231 | D112: 15847 | E112: 16695 | F112: 16991 | G112: 17210 | H112: 17456 | I112: 17623 | J112: 17684 | K112: 17733 | L112: 17714 | M112: 17659 | N112: 17543 | O112: 17414 | P112: 17298 | Q112: 17224 | R112: 17204 | S112: 17241 | T112: 17314 | U112: 17449 | V112: 17586 | W112: 17749 | X112: 17904 | Y112: 18046 | Z112: 18172 | AA112: 18269 | AB112: 18344 | AC112: 18377 | AD112: 18383 | AE112: 18362 | AF112: 18293 | AG112: 18222 | AH112: 18129 | AI112: 18004 | AJ112: 17885 | AK112: 17770 | AL112: 17669 | AM112: 17572 | AN112: 17496 | AO112: 17464
B113: 2 | C113: 18075 | D113: 17334 | E113: 15948 | F113: 16810 | G113: 17111 | H113: 17500 | I113: 17803 | J113: 17854 | K113: 17860 | L113: 17895 | M113: 17873 | N113: 17816 | O113: 17700 | P113: 17574 | Q113: 17463 | R113: 17394 | S113: 17376 | T113: 17416 | U113: 17491 | V113: 17629 | W113: 17772 | X113: 17936 | Y113: 18092 | Z113: 18237 | AA113: 18362 | AB113: 18458 | AC113: 18537 | AD113: 18567 | AE113: 18573 | AF113: 18552 | AG113: 18481 | AH113: 18410 | AI113: 18317 | AJ113: 18192 | AK113: 18070 | AL113: 17958 | AM113: 17859 | AN113: 17761 | AO113: 17684
B114: 3 | C114: 19107 | D114: 18182 | E114: 17448 | F114: 16064 | G114: 16934 | H114: 17395 | I114: 17853 | J114: 18043 | K114: 18036 | L114: 18024 | M114: 18055 | N114: 18027 | O114: 17970 | P114: 17857 | Q114: 17737 | R114: 17635 | S114: 17571 | T114: 17552 | U114: 17594 | V114: 17671 | W114: 17812 | X114: 17953 | Y114: 18117 | Z114: 18272 | AA114: 18422 | AB114: 18549 | AC114: 18646 | AD114: 18726 | AE114: 18758 | AF114: 18764 | AG114: 18743 | AH114: 18669 | AI114: 18597 | AJ114: 18506 | AK114: 18380 | AL114: 18258 | AM114: 18141 | AN114: 18046 | AO114: 17950
B115: 4 | C115: 20074 | D115: 19192 | E115: 18281 | F115: 17554 | G115: 16176 | H115: 17197 | I115: 17715 | J115: 18065 | K115: 18203 | L115: 18171 | M115: 18149 | N115: 18177 | O115: 18154 | P115: 18101 | Q115: 17989 | R115: 17871 | S115: 17770 | T115: 17711 | U115: 17697 | V115: 17743 | W115: 17824 | X115: 17965 | Y115: 18106 | Z115: 18270 | AA115: 18429 | AB115: 18582 | AC115: 18705 | AD115: 18804 | AE115: 18882 | AF115: 18916 | AG115: 18920 | AH115: 18900 | AI115: 18826 | AJ115: 18752 | AK115: 18661 | AL115: 18537 | AM115: 18417 | AN115: 18303 | AO115: 18204
B116: 5 | C116: 20408 | D116: 20159 | E116: 19279 | F116: 18375 | G116: 17648 | H116: 16443 | I116: 17519 | J116: 17909 | K116: 18201 | L116: 18322 | M116: 18278 | N116: 18248 | O116: 18270 | P116: 18252 | Q116: 18203 | R116: 18093 | S116: 17977 | T116: 17879 | U116: 17823 | V116: 17813 | W116: 17864 | X116: 17945 | Y116: 18084 | Z116: 18230 | AA116: 18393 | AB116: 18552 | AC116: 18709 | AD116: 18831 | AE116: 18931 | AF116: 19009 | AG116: 19043 | AH116: 19045 | AI116: 19029 | AJ116: 18954 | AK116: 18877 | AL116: 18784 | AM116: 18662 | AN116: 18539 | AO116: 18423
B117: 6 | C117: 19731 | D117: 20477 | E117: 20230 | F117: 19357 | G117: 18457 | H117: 17905 | I117: 16766 | J117: 17711 | K117: 18034 | L117: 18305 | M117: 18412 | N117: 18365 | O117: 18334 | P117: 18356 | Q117: 18339 | R117: 18292 | S117: 18183 | T117: 18072 | U117: 17977 | V117: 17923 | W117: 17915 | X117: 17964 | Y117: 18047 | Z117: 18185 | AA117: 18331 | AB117: 18494 | AC117: 18654 | AD117: 18812 | AE117: 18935 | AF117: 19034 | AG117: 19110 | AH117: 19144 | AI117: 19143 | AJ117: 19125 | AK117: 19049 | AL117: 18972 | AM117: 18882 | AN117: 18759 | AO117: 18637
B118: 7 | C118: 19212 | D118: 19786 | E118: 20540 | F118: 20294 | G118: 19431 | H118: 18709 | I118: 18229 | J118: 16948 | K118: 17821 | L118: 18123 | M118: 18382 | N118: 18480 | O118: 18430 | P118: 18399 | Q118: 18424 | R118: 18408 | S118: 18364 | T118: 18257 | U118: 18148 | V118: 18053 | W118: 18001 | X118: 17993 | Y118: 18045 | Z118: 18128 | AA118: 18267 | AB118: 18411 | AC118: 18575 | AD118: 18732 | AE118: 18888 | AF118: 19012 | AG118: 19109 | AH118: 19185 | AI118: 19217 | AJ118: 19216 | AK118: 19197 | AL118: 19122 | AM118: 19046 | AN118: 18954 | AO118: 18833
B119: 8 | C119: 19038 | D119: 19244 | E119: 19821 | F119: 20579 | G119: 20333 | H119: 19672 | I119: 19031 | J119: 18391 | K119: 17041 | L119: 17882 | M119: 18177 | N119: 18423 | O119: 18519 | P119: 18469 | Q119: 18441 | R119: 18467 | S119: 18452 | T119: 18410 | U119: 18303 | V119: 18194 | W119: 18101 | X119: 18051 | Y119: 18045 | Z119: 18098 | AA119: 18180 | AB119: 18324 | AC119: 18467 | AD119: 18630 | AE119: 18790 | AF119: 18947 | AG119: 19070 | AH119: 19167 | AI119: 19239 | AJ119: 19272 | AK119: 19274 | AL119: 19254 | AM119: 19181 | AN119: 19104 | AO119: 19011
B120: 9 | C120: 18810 | D120: 19061 | E120: 19266 | F120: 19847 | G120: 20607 | H120: 20558 | I120: 19973 | J120: 19187 | K120: 18464 | L120: 17090 | M120: 17916 | N120: 18201 | O120: 18443 | P120: 18539 | Q120: 18492 | R120: 18466 | S120: 18491 | T120: 18474 | U120: 18433 | V120: 18329 | W120: 18220 | X120: 18130 | Y120: 18082 | Z120: 18076 | AA120: 18130 | AB120: 18211 | AC120: 18354 | AD120: 18497 | AE120: 18658 | AF120: 18818 | AG120: 18975 | AH120: 19097 | AI120: 19193 | AJ120: 19265 | AK120: 19298 | AL120: 19300 | AM120: 19280 | AN120: 19207 | AO120: 19129
B121: 10 | C121: 19404 | D121: 18821 | E121: 19072 | F121: 19279 | G121: 19867 | H121: 20835 | I121: 20859 | J121: 20125 | K121: 19256 | L121: 18507 | M121: 17112 | N121: 17924 | O121: 18203 | P121: 18447 | Q121: 18543 | R121: 18496 | S121: 18470 | T121: 18496 | U121: 18480 | V121: 18439 | W121: 18338 | X121: 18230 | Y121: 18141 | Z121: 18096 | AA121: 18090 | AB121: 18145 | AC121: 18227 | AD121: 18374 | AE121: 18518 | AF121: 18678 | AG121: 18838 | AH121: 18995 | AI121: 19116 | AJ121: 19210 | AK121: 19282 | AL121: 19314 | AM121: 19315 | AN121: 19293 | AO121: 19221
B122: 11 | C122: 19519 | D122: 19403 | E122: 18824 | F122: 19076 | G122: 19288 | H122: 20069 | I122: 21109 | J122: 20980 | K122: 20175 | L122: 19278 | M122: 18517 | N122: 17115 | O122: 17923 | P122: 18202 | Q122: 18444 | R122: 18540 | S122: 18493 | T122: 18467 | U122: 18492 | V122: 18477 | W122: 18436 | X122: 18337 | Y122: 18229 | Z122: 18142 | AA122: 18096 | AB122: 18092 | AC122: 18145 | AD122: 18226 | AE122: 18372 | AF122: 18519 | AG122: 18681 | AH122: 18841 | AI122: 18996 | AJ122: 19118 | AK122: 19211 | AL122: 19282 | AM122: 19313 | AN122: 19313 | AO122: 19291
... B210: 99 | C210: 77 | D210: 71 | E210: 68 | F210: 81 | G210: 87 | H210: 112 | I210: 122 | J210: 159 | K210: 166 | L210: 181 | M210: 176 | N210: 192 | O210: 210 | P210: 233 | Q210: 239 | R210: 244 | S210: 264 | T210: 279 | U210: 256 | V210: 242 | W210: 292 | X210: 325 | Y210: 346 | Z210: 411 | AA210: 499 | AB210: 552 | AC210: 579 | AD210: 638 | AE210: 698 | AF210: 747 | AG210: 793 | AH210: 842 | AI210: 911 | AJ210: 937 | AK210: 998 | AL210: 1046 | AM210: 1063 | AN210: 1063 | AO210: 1051
B211: 100+ | C211: 94 | D211: 113 | E211: 118 | F211: 117 | G211: 132 | H211: 145 | I211: 175 | J211: 206 | K211: 253 | L211: 291 | M211: 330 | N211: 355 | O211: 383 | P211: 417 | Q211: 458 | R211: 492 | S211: 522 | T211: 553 | U211: 586 | V211: 599 | W211: 605 | X211: 647 | Y211: 701 | Z211: 755 | AA211: 843 | AB211: 978 | AC211: 1118 | AD211: 1244 | AE211: 1382 | AF211: 1528 | AG211: 1681 | AH211: 1828 | AI211: 1974 | AJ211: 2148 | AK211: 2299 | AL211: 2464 | AM211: 2627 | AN211: 2771 | AO211: 2887
A212: Kobiety Females | B212: Ogółem Total | C212: 1765923 | D212: 1766849 | E212: 1768272 | F212: 1770022 | G212: 1772142 | H212: 1783165 | I212: 1797670 | J212: 1805110 | K212: 1808837 | L212: 1811246 | M212: 1812762 | N212: 1813720 | O212: 1814177 | P212: 1814298 | Q212: 1814323 | R212: 1814120 | S212: 1813711 | T212: 1813393 | U212: 1812937 | V212: 1812575 | W212: 1812141 | X212: 1811576 | Y212: 1811119 | Z212: 1810479 | AA212: 1809704 | AB212: 1809004 | AC212: 1808062 | AD212: 1807000 | AE212: 1805982 | AF212: 1804749 | AG212: 1803260 | AH212: 1801769 | AI212: 1800056 | AJ212: 1798351 | AK212: 1796435 | AL212: 1794326 | AM212: 1792236 | AN212: 1790014 | AO212: 1787609
B213: 0 | C213: 14933 | D213: 15626 | E213: 15894 | F213: 16091 | G213: 16221 | H213: 16329 | I213: 16462 | J213: 16546 | K213: 16522 | L213: 16468 | M213: 16358 | N213: 16235 | O213: 16119 | P213: 16042 | Q213: 16016 | R213: 16048 | S213: 16112 | T213: 16233 | U213: 16363 | V213: 16521 | W213: 16668 | X213: 16803 | Y213: 16924 | Z213: 17012 | AA213: 17073 | AB213: 17114 | AC213: 17116 | AD213: 17101 | AE213: 17033 | AF213: 16967 | AG213: 16873 | AH213: 16760 | AI213: 16637 | AJ213: 16540 | AK213: 16437 | AL213: 16350 | AM213: 16280 | AN213: 16245 | AO213: 16217
B214: 1 | C214: 16463 | D214: 15026 | E214: 15728 | F214: 16003 | G214: 16209 | H214: 16448 | I214: 16598 | J214: 16663 | K214: 16707 | L214: 16676 | M214: 16622 | N214: 16514 | O214: 16390 | P214: 16280 | Q214: 16210 | R214: 16188 | S214: 16224 | T214: 16291 | U214: 16417 | V214: 16553 | W214: 16709 | X214: 16857 | Y214: 16992 | Z214: 17116 | AA214: 17202 | AB214: 17261 | AC214: 17302 | AD214: 17305 | AE214: 17289 | AF214: 17221 | AG214: 17157 | AH214: 17063 | AI214: 16948 | AJ214: 16825 | AK214: 16730 | AL214: 16627 | AM214: 16543 | AN214: 16478 | AO214: 16442
...

Sheet Tabl. 2
C1: TABL. 2. LUDNOŚĆ WEDŁUG PŁCI I PIĘCIOLETNICH GRUP WIEKU
A2: Powrót do spisu tablic | D2: Stan w dniu 31 XII
A3: Return to the list of tables | D3: POPULATION BY SEX AND 5-YEAR AGE GROUPS
D4: As of 31 XII
D5: * dane empiryczne empirical data
A6: małopolskie
A7: Płeć Sex | B7: Grupa wieku Age group | C7: 2022* | D7: 2023 | E7: 2024 | F7: 2025 | G7: 2026 | H7: 2027 | I7: 2028 | J7: 2029 | K7: 2030 | L7: 2031 | M7: 2032 | N7: 2033 | O7: 2034 | P7: 2035 | Q7: 2036 | R7: 2037 | S7: 2038 | T7: 2039 | U7: 2040 | V7: 2041 | W7: 2042 | X7: 2043 | Y7: 2044 | Z7: 2045 | AA7: 2046 | AB7: 2047 | AC7: 2048 | AD7: 2049 | AE7: 2050 | AF7: 2051 | AG7: 2052 | AH7: 2053 | AI7: 2054 | AJ7: 2055 | AK7: 2056 | AL7: 2057 | AM7: 2058 | AN7: 2059 | AO7: 2060
A8: Ogółem Total | B8: Ogółem Total | C8: 3429014 | D8: 3430361 | E8: 3432698 | F8: 3435619 | G8: 3439093 | H8: 3456350 | I8: 3478788 | J8: 3490538 | K8: 3496654 | L8: 3500645 | M8: 3503222 | N8: 3504826 | O8: 3505452 | P8: 3505638 | Q8: 3505601 | R8: 3505303 | S8: 3504832 | T8: 3504305 | U8: 3503693 | V8: 3503292 | W8: 3502945 | X8: 3502554 | Y8: 3502396 | Z8: 3501931 | AA8: 3501425 | AB8: 3501031 | AC8: 3500425 | AD8: 3499641 | AE8: 3498662 | AF8: 3497419 | AG8: 3495862 | AH8: 3494207 | AI8: 3492184 | AJ8: 3490127 | AK8: 3487547 | AL8: 3484688 | AM8: 3481818 | AN8: 3478783 | AO8: 3475560
B9: 0-4 | C9: 175623 | D9: 169831 | E9: 165828 | F9: 164373 | G9: 164437 | H9: 168674 | I9: 171750 | J9: 173172 | K9: 173478 | L9: 173312 | M9: 172950 | N9: 172347 | O9: 171454 | P9: 170509 | Q9: 169638 | R9: 169083 | S9: 168925 | T9: 169247 | U9: 169985 | V9: 171084 | W9: 172408 | X9: 173859 | Y9: 175291 | Z9: 176633 | AA9: 177796 | AB9: 178726 | AC9: 179381 | AD9: 179764 | AE9: 179816 | AF9: 179598 | AG9: 179101 | AH9: 178370 | AI9: 177420 | AJ9: 176395 | AK9: 175305 | AL9: 174226 | AM9: 173240 | AN9: 172433 | AO9: 171774
B10: 5-9 | C10: 188614 | D10: 191308 | E10: 192463 | F10: 191176 | G10: 187543 | H10: 181544 | I10: 178381 | J10: 175417 | K10: 174271 | L10: 174327 | M10: 176989 | N10: 178017 | O10: 178536 | P10: 178553 | Q10: 178323 | R10: 177997 | S10: 177493 | T10: 176751 | U10: 175951 | V10: 175220 | W10: 174805 | X10: 174760 | Y10: 175184 | Z10: 176005 | AA10: 177163 | AB10: 178527 | AC10: 180020 | AD10: 181485 | AE10: 182845 | AF10: 184022 | AG10: 184965 | AH10: 185620 | AI10: 185979 | AJ10: 186003 | AK10: 185756 | AL10: 185238 | AM10: 184493 | AN10: 183529 | AO10: 182507
B11: 10-14 | C11: 194346 | D11: 191865 | E11: 189019 | F11: 186802 | G11: 187510 | H11: 191532 | I11: 196897 | J11: 199356 | K11: 198633 | L11: 195142 | M11: 187234 | N11: 181383 | O11: 177146 | P11: 175456 | Q11: 175221 | R11: 177739 | S11: 178743 | T11: 179283 | U11: 179326 | V11: 179132 | W11: 178849 | X11: 178395 | Y11: 177708 | Z11: 176967 | AA11: 176296 | AB11: 175941 | AC11: 175944 | AD11: 176394 | AE11: 177245 | AF11: 178423 | AG11: 179796 | AH11: 181300 | AI11: 182768 | AJ11: 184121 | AK11: 185265 | AL11: 186170 | AM11: 186794 | AN11: 187137 | AO11: 187140
B12: 15-19 | C12: 168574 | D12: 175383 | E12: 182691 | F12: 188872 | G12: 192786 | H12: 196008 | I12: 195721 | J12: 194008 | K12: 192315 | L12: 193382 | M12: 195853 | N12: 198775 | O12: 200077 | P12: 198824 | Q12: 195039 | R12: 186971 | S12: 181065 | T12: 176796 | U12: 175077 | V12: 174810 | W12: 177297 | X12: 178286 | Y12: 178825 | Z12: 178881 | AA12: 178710 | AB12: 178449 | AC12: 178026 | AD12: 177373 | AE12: 176663 | AF12: 176031 | AG12: 175712 | AH12: 175747 | AI12: 176224 | AJ12: 177103 | AK12: 178303 | AL12: 179687 | AM12: 181180 | AN12: 182629 | AO12: 183955
B13: 20-24 | C13: 178649 | D13: 172813 | E13: 168839 | F13: 166049 | G13: 165807 | H13: 169656 | I13: 177519 | J13: 185624 | K13: 192499 | L13: 196981 | M13: 199305 | N13: 197431 | O13: 194966 | P13: 192979 | Q13: 193889 | R13: 196258 | S13: 199096 | T13: 200352 | U13: 199074 | V13: 195261 | W13: 187154 | X13: 181211 | Y13: 176918 | Z13: 175162 | AA13: 174876 | AB13: 177338 | AC13: 178309 | AD13: 178844 | AE13: 178900 | AF13: 178735 | AG13: 178485 | AH13: 178081 | AI13: 177454 | AJ13: 176778 | AK13: 176188 | AL13: 175903 | AM13: 175965 | AN13: 176471 | AO13: 177367
B14: 25-29 | C14: 218362 | D14: 209471 | E14: 200511 | F14: 194169 | G14: 187662 | H14: 182304 | I14: 177619 | J14: 174258 | K14: 171739 | L14: 171647 | M14: 175033 | N14: 182188 | O14: 190059 | P14: 196900 | Q14: 201337 | R14: 203581 | S14: 201611 | T14: 199032 | U14: 196946 | V14: 197800 | W14: 200135 | X14: 202936 | Y14: 204120 | Z14: 202737 | AA14: 198758 | AB14: 190456 | AC14: 184334 | AD14: 179875 | AE14: 178016 | AF14: 177669 | AG14: 180091 | AH14: 181038 | AI14: 181580 | AJ14: 181657 | AK14: 181524 | AL14: 181311 | AM14: 180953 | AN14: 180376 | AO14: 179747
B15: 30-34 | C15: 263005 | D15: 257899 | E15: 252204 | F15: 243662 | G15: 232896 | H15: 223957 | I15: 216512 | J15: 208064 | K15: 201849 | L15: 195315 | M15: 189139 | N15: 183457 | O15: 179746 | P15: 177208 | Q15: 177262 | R15: 180871 | S15: 188260 | T15: 196320 | U15: 203247 | V15: 207656 | W15: 209805 | X15: 207699 | Y15: 205014 | Z15: 202860 | AA15: 203672 | AB15: 206000 | AC15: 208713 | AD15: 209737 | AE15: 208171 | AF15: 203945 | AG15: 195381 | AH15: 189079 | AI15: 184498 | AJ15: 182544 | AK15: 182146 | AL15: 184556 | AM15: 185511 | AN15: 186070 | AO15: 186177
B16: 35-39 | C16: 286407 | D16: 280323 | E16: 274057 | F16: 269269 | G16: 267493 | H16: 265994 | I16: 262609 | J16: 257591 | K16: 249239 | L16: 238544 | M16: 228552 | N16: 219578 | O16: 210497 | P16: 204092 | Q16: 197512 | R16: 191407 | S16: 185863 | T16: 182323 | U16: 179981 | V16: 180222 | W16: 183986 | X16: 191477 | Y16: 199619 | Z16: 206532 | AA16: 210879 | AB16: 212954 | AC16: 210818 | AD16: 208108 | AE16: 205940 | AF16: 206723 | AG16: 209037 | AH16: 211677 | AI16: 212585 | AJ16: 210893 | AK16: 206556 | AL16: 197919 | AM16: 191581 | AN16: 186988 | AO16: 185004
B17: 40-44 | C17: 276280 | D17: 282141 | E17: 286432 | F17: 288542 | G17: 289068 | H17: 286583 | I17: 281996 | J17: 276578 | K17: 272177 | L17: 270603 | M17: 267893 | N17: 262763 | O17: 256943 | P17: 248366 | Q17: 237677 | R17: 227757 | S17: 218916 | T17: 209974 | U17: 203703 | V17: 197291 | W17: 191324 | X17: 185942 | Y17: 182562 | Z17: 180365 | AA17: 180694 | AB17: 184503 | AC17: 192009 | AD17: 200126 | AE17: 206990 | AF17: 211302 | AG17: 213354 | AH17: 211211 | AI17: 208515 | AJ17: 206371 | AK17: 207147 | AL17: 209415 | AM17: 212000 | AN17: 212846 | AO17: 211127
B18: 45-49 | C18: 250064 | D18: 256772 | E18: 261760 | F18: 266624 | G18: 268909 | H18: 274216 | I18: 281102 | J18: 285963 | K18: 288437 | L18: 289178 | M18: 285920 | N18: 280111 | O18: 274147 | P18: 269507 | Q18: 267784 | R18: 265004 | S18: 259895 | T18: 254145 | U18: 245665 | V18: 235155 | W18: 225482 | X18: 216814 | Y18: 208055 | Z18: 201942 | AA18: 195697 | AB18: 189892 | AC18: 184645 | AD18: 181374 | AE18: 179295 | AF18: 179684 | AG18: 183502 | AH18: 190972 | AI18: 199027 | AJ18: 205829 | AK18: 210101 | AL18: 212149 | AM18: 210035 | AN18: 207367 | AO18: 205243
B19: 50-44 | C19: 211594 | D19: 216951 | E19: 224122 | F19: 230979 | G19: 238935 | H19: 246252 | I19: 253664 | J19: 259058 | K19: 264136 | L19: 266605 | M19: 271333 | N19: 277334 | O19: 281762 | P19: 284060 | Q19: 284695 | R19: 281423 | S19: 275711 | T19: 269853 | U19: 265296 | V19: 263584 | W19: 260818 | X19: 255801 | Y19: 250150 | Z19: 241858 | AA19: 231598 | AB19: 222178 | AC19: 213751 | AD19: 205216 | AE19: 199274 | AF19: 193209 | AG19: 187576 | AH19: 182502 | AI19: 179365 | AJ19: 177410 | AK19: 177860 | AL19: 181688 | AM19: 189102 | AN19: 197092 | AO19: 203830
B20: 55-59 | C20: 197986 | D20: 196908 | E20: 196896 | F20: 198487 | G20: 201388 | H20: 206012 | I20: 211954 | J20: 219324 | K20: 226264 | L20: 234228 | M20: 241060 | N20: 247768 | O20: 252825 | P20: 257721 | Q20: 260151 | R20: 264834 | S20: 270780 | T20: 275169 | U20: 277460 | V20: 278129 | W20: 274961 | X20: 269400 | Y20: 263751 | Z20: 259339 | AA20: 257699 | AB20: 255026 | AC20: 250163 | AD20: 244700 | AE20: 236676 | AF20: 226740 | AG20: 217616 | AH20: 209452 | AI20: 201195 | AJ20: 195460 | AK20: 189623 | AL20: 184180 | AM20: 179293 | AN20: 176306 | AO20: 174494
... B29: 100+ | C29: 472 | D29: 536 | E29: 571 | F29: 653 | G29: 738 | H29: 809 | I29: 924 | J29: 1049 | K29: 1219 | L29: 1371 | M29: 1533 | N29: 1647 | O29: 1757 | P29: 1903 | Q29: 2071 | R29: 2202 | S29: 2325 | T29: 2465 | U29: 2566 | V29: 2582 | W29: 2581 | X29: 2692 | Y29: 2899 | Z29: 3082 | AA29: 3432 | AB29: 3894 | AC29: 4376 | AD29: 4831 | AE29: 5300 | AF29: 5821 | AG29: 6322 | AH29: 6805 | AI29: 7271 | AJ29: 7829 | AK29: 8306 | AL29: 8796 | AM29: 9288 | AN29: 9702 | AO29: 10041
A30: Mężczyźni Males | B30: Ogółem Total | C30: 1663091 | D30: 1663512 | E30: 1664426 | F30: 1665597 | G30: 1666951 | H30: 1673185 | I30: 1681118 | J30: 1685428 | K30: 1687817 | L30: 1689399 | M30: 1690460 | N30: 1691106 | O30: 1691275 | P30: 1691340 | Q30: 1691278 | R30: 1691183 | S30: 1691121 | T30: 1690912 | U30: 1690756 | V30: 1690717 | W30: 1690804 | X30: 1690978 | Y30: 1691277 | Z30: 1691452 | AA30: 1691721 | AB30: 1692027 | AC30: 1692363 | AD30: 1692641 | AE30: 1692680 | AF30: 1692670 | AG30: 1692602 | AH30: 1692438 | AI30: 1692128 | AJ30: 1691776 | AK30: 1691112 | AL30: 1690362 | AM30: 1689582 | AN30: 1688769 | AO30: 1687951
B31: 0-4 | C31: 90215 | D31: 87122 | E31: 85232 | F31: 84485 | G31: 84632 | H31: 86868 | I31: 88450 | J31: 89188 | K31: 89355 | L31: 89275 | M31: 89091 | N31: 88788 | O31: 88341 | P31: 87856 | Q31: 87408 | R31: 87129 | S31: 87052 | T31: 87217 | U31: 87595 | V31: 88154 | W31: 88839 | X31: 89579 | Y31: 90309 | Z31: 90995 | AA31: 91601 | AB31: 92087 | AC31: 92426 | AD31: 92624 | AE31: 92649 | AF31: 92527 | AG31: 92271 | AH31: 91890 | AI31: 91408 | AJ31: 90884 | AK31: 90327 | AL31: 89772 | AM31: 89264 | AN31: 88845 | AO31: 88508
B32: 5-9 | C32: 97199 | D32: 98727 | E32: 99136 | F32: 98452 | G32: 96476 | H32: 93287 | I32: 91518 | J32: 90146 | K32: 89561 | L32: 89722 | M32: 91165 | N32: 91717 | O32: 91996 | P32: 92015 | Q32: 91899 | R32: 91726 | S32: 91467 | T32: 91092 | U32: 90684 | V32: 90312 | W32: 90101 | X32: 90083 | Y32: 90303 | Z32: 90717 | AA32: 91301 | AB32: 91992 | AC32: 92759 | AD32: 93502 | AE32: 94202 | AF32: 94820 | AG32: 95307 | AH32: 95638 | AI32: 95821 | AJ32: 95832 | AK32: 95695 | AL32: 95432 | AM32: 95051 | AN32: 94563 | AO32: 94033
B33: 10-14 | C33: 99741 | D33: 98688 | E33: 97330 | F33: 96065 | G33: 96449 | H33: 98625 | I33: 101493 | J33: 102574 | K33: 102177 | L33: 100278 | M33: 96134 | N33: 93008 | O33: 90985 | P33: 90130 | Q33: 90140 | R33: 91506 | S33: 92046 | T33: 92332 | U33: 92361 | V33: 92257 | W33: 92104 | X33: 91869 | Y33: 91522 | Z33: 91145 | AA33: 90803 | AB33: 90622 | AC33: 90624 | AD33: 90859 | AE33: 91284 | AF33: 91878 | AG33: 92576 | AH33: 93352 | AI33: 94098 | AJ33: 94795 | AK33: 95395 | AL33: 95863 | AM33: 96179 | AN33: 96352 | AO33: 96357
B34: 15-19 | C34: 86179 | D34: 89611 | E34: 93214 | F34: 96587 | G34: 98806 | H34: 100456 | I34: 100511 | J34: 99715 | K34: 98706 | L34: 99259 | M34: 100664 | N34: 102311 | O34: 102815 | P34: 102164 | Q34: 100127 | R34: 95903 | S34: 92752 | T34: 90716 | U34: 89840 | V34: 89835 | W34: 91184 | X34: 91716 | Y34: 92002 | Z34: 92038 | AA34: 91948 | AB34: 91806 | AC34: 91587 | AD34: 91259 | AE34: 90897 | AF34: 90577 | AG34: 90411 | AH34: 90431 | AI34: 90682 | AJ34: 91124 | AK34: 91731 | AL34: 92434 | AM34: 93210 | AN34: 93948 | AO34: 94630
B35: 20-24 | C35: 90424 | D35: 87678 | E35: 85984 | F35: 84669 | G35: 84508 | H35: 86356 | I35: 90101 | J35: 94072 | K35: 97861 | L35: 100454 | M35: 101754 | N35: 101099 | O35: 99973 | P35: 98839 | Q35: 99322 | R35: 100674 | S35: 102285 | T35: 102767 | U35: 102112 | V35: 100067 | W35: 95847 | X35: 92693 | Y35: 90651 | Z35: 89759 | AA35: 89742 | AB35: 91079 | AC35: 91609 | AD35: 91891 | AE35: 91931 | AF35: 91843 | AG35: 91709 | AH35: 91499 | AI35: 91182 | AJ35: 90841 | AK35: 90546 | AL35: 90401 | AM35: 90432 | AN35: 90699 | AO35: 91147
B36: 25-29 | C36: 109567 | D36: 105068 | E36: 100653 | F36: 97609 | G36: 94404 | H36: 91587 | I36: 89133 | J36: 87599 | K36: 86378 | L36: 86288 | M36: 88042 | N36: 91639 | O36: 95584 | P36: 99385 | Q36: 101967 | R36: 103244 | S36: 102558 | T36: 101397 | U36: 100235 | V36: 100697 | W36: 102011 | X36: 103598 | Y36: 104073 | Z36: 103390 | AA36: 101296 | AB36: 97026 | AC36: 93816 | AD36: 91720 | AE36: 90795 | AF36: 90765 | AG36: 92095 | AH36: 92616 | AI36: 92903 | AJ36: 92954 | AK36: 92879 | AL36: 92761 | AM36: 92573 | AN36: 92277 | AO36: 91955
B37: 30-34 | C37: 132641 | D37: 129780 | E37: 126837 | F37: 122150 | G37: 116607 | H37: 111691 | I37: 107573 | J37: 103323 | K37: 100344 | L37: 97165 | M37: 94177 | N37: 91527 | O37: 89948 | P37: 88763 | Q37: 88777 | R37: 90648 | S37: 94351 | T37: 98378 | U37: 102209 | V37: 104781 | W37: 106030 | X37: 105280 | Y37: 104072 | Z37: 102890 | AA37: 103326 | AB37: 104631 | AC37: 106191 | AD37: 106601 | AE37: 105855 | AF37: 103682 | AG37: 99316 | AH37: 96046 | AI37: 93912 | AJ37: 92957 | AK37: 92901 | AL37: 94233 | AM37: 94760 | AN37: 95061 | AO37: 95134
B38: 35-39 | C38: 143998 | D38: 141348 | E38: 138093 | F38: 135892 | G38: 134900 | H38: 133691 | I38: 131225 | J38: 128447 | K38: 123854 | L38: 118411 | M38: 113333 | N38: 108913 | O38: 104557 | P38: 101568 | Q38: 98419 | R38: 95513 | S38: 92943 | T38: 91467 | U38: 90397 | V38: 90500 | W38: 92432 | X38: 96188 | Y38: 100264 | Z38: 104087 | AA38: 106636 | AB38: 107866 | AC38: 107108 | AD38: 105897 | AE38: 104710 | AF38: 105132 | AG38: 106425 | AH38: 107951 | AI38: 108325 | AJ38: 107528 | AK38: 105314 | AL38: 100929 | AM38: 97656 | AN38: 95525 | AO38: 94559
B39: 40-44 | C39: 138842 | D39: 141410 | E39: 143354 | F39: 144442 | G39: 144898 | H39: 143494 | I39: 141168 | J39: 138120 | K39: 136023 | L39: 135077 | M39: 133620 | N39: 130823 | O39: 127903 | P39: 123313 | Q39: 117952 | R39: 112958 | S39: 108648 | T39: 104371 | U39: 101464 | V39: 98416 | W39: 95590 | X39: 93107 | Y39: 91711 | Z39: 90721 | AA39: 90874 | AB39: 92851 | AC39: 96622 | AD39: 100682 | AE39: 104467 | AF39: 106989 | AG39: 108211 | AH39: 107451 | AI39: 106245 | AJ39: 105081 | AK39: 105509 | AL39: 106771 | AM39: 108264 | AN39: 108610 | AO39: 107814
B40: 45-49 | C40: 124684 | D40: 128094 | E40: 130880 | F40: 133516 | G40: 134630 | H40: 137029 | I40: 139813 | J40: 141864 | K40: 143016 | L40: 143489 | M40: 141950 | N40: 139420 | O40: 136319 | P40: 134211 | Q40: 133241 | R40: 131788 | S40: 129032 | T40: 126178 | U40: 121668 | V40: 116427 | W40: 111588 | X40: 107395 | Y40: 103249 | Z40: 100438 | AA40: 97495 | AB40: 94768 | AC40: 92371 | AD40: 91041 | AE40: 90131 | AF40: 90316 | AG40: 92285 | AH40: 96036 | AI40: 100059 | AJ40: 103806 | AK40: 106289 | AL40: 107511 | AM40: 106771 | AN40: 105583 | AO40: 104436
B41: 50-44 | C41: 104881 | D41: 107244 | E41: 110739 | F41: 114012 | G41: 117798 | H41: 121540 | I41: 125043 | J41: 127906 | K41: 130581 | L41: 131753 | M41: 134033 | N41: 136644 | O41: 138613 | P41: 139729 | Q41: 140177 | R41: 138665 | S41: 136225 | T41: 133213 | U41: 131170 | V41: 130226 | W41: 128801 | X41: 126107 | Y41: 123328 | Z41: 118958 | AA41: 113902 | AB41: 109249 | AC41: 105226 | AD41: 101237 | AE41: 98543 | AF41: 95724 | AG41: 93114 | AH41: 90827 | AI41: 89566 | AJ41: 88732 | AK41: 88959 | AL41: 90932 | AM41: 94639 | AN41: 98618 | AO41: 102318
B42: 55-59 | C42: 97382 | D42: 96906 | E42: 96724 | F42: 97331 | G42: 98785 | H42: 100473 | I42: 102923 | J42: 106410 | K42: 109671 | L42: 113437 | M42: 117053 | N42: 120395 | O42: 123152 | P42: 125747 | Q42: 126919 | R42: 129200 | S42: 131795 | T42: 133758 | U42: 134884 | V42: 135359 | W42: 133924 | X42: 131595 | Y42: 128742 | Z42: 126817 | AA42: 125945 | AB42: 124603 | AC42: 122035 | AD42: 119397 | AE42: 115220 | AF42: 110393 | AG42: 105957 | AH42: 102127 | AI42: 98329 | AJ42: 95783 | AK42: 93114 | AL42: 90638 | AM42: 88472 | AN42: 87307 | AO42: 86569
... B51: 100+ | C51: 94 | D51: 113 | E51: 118 | F51: 117 | G51: 132 | H51: 145 | I51: 175 | J51: 206 | K51: 253 | L51: 291 | M51: 330 | N51: 355 | O51: 383 | P51: 417 | Q51: 458 | R51: 492 | S51: 522 | T51: 553 | U51: 586 | V51: 599 | W51: 605 | X51: 647 | Y51: 701 | Z51: 755 | AA51: 843 | AB51: 978 | AC51: 1118 | AD51: 1244 | AE51: 1382 | AF51: 1528 | AG51: 1681 | AH51: 1828 | AI51: 1974 | AJ51: 2148 | AK51: 2299 | AL51: 2464 | AM51: 2627 | AN51: 2771 | AO51: 2887
A52: Kobiety Females | B52: Ogółem Total | C52: 1765923 | D52: 1766849 | E52: 1768272 | F52: 1770022 | G52: 1772142 | H52: 1783165 | I52: 1797670 | J52: 1805110 | K52: 1808837 | L52: 1811246 | M52: 1812762 | N52: 1813720 | O52: 1814177 | P52: 1814298 | Q52: 1814323 | R52: 1814120 | S52: 1813711 | T52: 1813393 | U52: 1812937 | V52: 1812575 | W52: 1812141 | X52: 1811576 | Y52: 1811119 | Z52: 1810479 | AA52: 1809704 | AB52: 1809004 | AC52: 1808062 | AD52: 1807000 | AE52: 1805982 | AF52: 1804749 | AG52: 1803260 | AH52: 1801769 | AI52: 1800056 | AJ52: 1798351 | AK52: 1796435 | AL52: 1794326 | AM52: 1792236 | AN52: 1790014 | AO52: 1787609
B53: 0-4 | C53: 85408 | D53: 82709 | E53: 80596 | F53: 79888 | G53: 79805 | H53: 81806 | I53: 83300 | J53: 83984 | K53: 84123 | L53: 84037 | M53: 83859 | N53: 83559 | O53: 83113 | P53: 82653 | Q53: 82230 | R53: 81954 | S53: 81873 | T53: 82030 | U53: 82390 | V53: 82930 | W53: 83569 | X53: 84280 | Y53: 84982 | Z53: 85638 | AA53: 86195 | AB53: 86639 | AC53: 86955 | AD53: 87140 | AE53: 87167 | AF53: 87071 | AG53: 86830 | AH53: 86480 | AI53: 86012 | AJ53: 85511 | AK53: 84978 | AL53: 84454 | AM53: 83976 | AN53: 83588 | AO53: 83266
B54: 5-9 | C54: 91415 | D54: 92581 | E54: 93327 | F54: 92724 | G54: 91067 | H54: 88257 | I54: 86863 | J54: 85271 | K54: 84710 | L54: 84605 | M54: 85824 | N54: 86300 | O54: 86540 | P54: 86538 | Q54: 86424 | R54: 86271 | S54: 86026 | T54: 85659 | U54: 85267 | V54: 84908 | W54: 84704 | X54: 84677 | Y54: 84881 | Z54: 85288 | AA54: 85862 | AB54: 86535 | AC54: 87261 | AD54: 87983 | AE54: 88643 | AF54: 89202 | AG54: 89658 | AH54: 89982 | AI54: 90158 | AJ54: 90171 | AK54: 90061 | AL54: 89806 | AM54: 89442 | AN54: 88966 | AO54: 88474
B55: 10-14 | C55: 94605 | D55: 93177 | E55: 91689 | F55: 90737 | G55: 91061 | H55: 92907 | I55: 95404 | J55: 96782 | K55: 96456 | L55: 94864 | M55: 91100 | N55: 88375 | O55: 86161 | P55: 85326 | Q55: 85081 | R55: 86233 | S55: 86697 | T55: 86951 | U55: 86965 | V55: 86875 | W55: 86745 | X55: 86526 | Y55: 86186 | Z55: 85822 | AA55: 85493 | AB55: 85319 | AC55: 85320 | AD55: 85535 | AE55: 85961 | AF55: 86545 | AG55: 87220 | AH55: 87948 | AI55: 88670 | AJ55: 89326 | AK55: 89870 | AL55: 90307 | AM55: 90615 | AN55: 90785 | AO55: 90783
B56: 15-19 | C56: 82395 | D56: 85772 | E56: 89477 | F56: 92285 | G56: 93980 | H56: 95552 | I56: 95210 | J56: 94293 | K56: 93609 | L56: 94123 | M56: 95189 | N56: 96464 | O56: 97262 | P56: 96660 | Q56: 94912 | R56: 91068 | S56: 88313 | T56: 86080 | U56: 85237 | V56: 84975 | W56: 86113 | X56: 86570 | Y56: 86823 | Z56: 86843 | AA56: 86762 | AB56: 86643 | AC56: 86439 | AD56: 86114 | AE56: 85766 | AF56: 85454 | AG56: 85301 | AH56: 85316 | AI56: 85542 | AJ56: 85979 | AK56: 86572 | AL56: 87253 | AM56: 87970 | AN56: 88681 | AO56: 89325
...

Sheet Tabl. 3
C1: TABL. 3. LUDNOŚĆ WEDŁUG PŁCI I WYBRANYCH GRUP WIEKU
A2: Powrót do spisu tablic | D2: Stan w dniu 31 XII
A3: Return to the list of tables | D3: POPULATION BY SEX AND SELECTED GROUPS OF AGE
D4: As of 31 XII
D5: * dane empiryczne empirical data
A6: małopolskie
A7: Płeć Sex | B7: Grupa wieku Age group | C7: 2022* | D7: 2023 | E7: 2024 | F7: 2025 | G7: 2026 | H7: 2027 | I7: 2028 | J7: 2029 | K7: 2030 | L7: 2031 | M7: 2032 | N7: 2033 | O7: 2034 | P7: 2035 | Q7: 2036 | R7: 2037 | S7: 2038 | T7: 2039 | U7: 2040 | V7: 2041 | W7: 2042 | X7: 2043 | Y7: 2044 | Z7: 2045 | AA7: 2046 | AB7: 2047 | AC7: 2048 | AD7: 2049 | AE7: 2050 | AF7: 2051 | AG7: 2052 | AH7: 2053 | AI7: 2054 | AJ7: 2055 | AK7: 2056 | AL7: 2057 | AM7: 2058 | AN7: 2059 | AO7: 2060
A8: Ogółem Total | B8: Ogółem Total | C8: 3429014 | D8: 3430361 | E8: 3432698 | F8: 3435619 | G8: 3439093 | H8: 3456350 | I8: 3478788 | J8: 3490538 | K8: 3496654 | L8: 3500645 | M8: 3503222 | N8: 3504826 | O8: 3505452 | P8: 3505638 | Q8: 3505601 | R8: 3505303 | S8: 3504832 | T8: 3504305 | U8: 3503693 | V8: 3503292 | W8: 3502945 | X8: 3502554 | Y8: 3502396 | Z8: 3501931 | AA8: 3501425 | AB8: 3501031 | AC8: 3500425 | AD8: 3499641 | AE8: 3498662 | AF8: 3497419 | AG8: 3495862 | AH8: 3494207 | AI8: 3492184 | AJ8: 3490127 | AK8: 3487547 | AL8: 3484688 | AM8: 3481818 | AN8: 3478783 | AO8: 3475560
B9: 0-17 | C9: 662369 | D9: 662344 | E9: 662373 | F9: 660912 | G9: 657007 | H9: 658226 | I9: 661786 | J9: 662470 | K9: 660840 | L9: 659486 | M9: 657044 | N9: 653642 | O9: 648667 | P9: 642137 | Q9: 636263 | R9: 631644 | S9: 629311 | T9: 628564 | U9: 630977 | V9: 632281 | W9: 633415 | X9: 634399 | Y9: 635502 | Z9: 636923 | AA9: 638528 | AB9: 640165 | AC9: 641866 | AD9: 643620 | AE9: 645431 | AF9: 647310 | AG9: 649157 | AH9: 650874 | AI9: 652315 | AJ9: 653415 | AK9: 654134 | AL9: 654376 | AM9: 654179 | AN9: 653570 | AO9: 652587
B10: 18-59/64 | C10: 2045737 | D10: 2035297 | E10: 2026260 | F10: 2020437 | G10: 2018860 | H10: 2025430 | I10: 2034708 | J10: 2036701 | K10: 2035629 | L10: 2032655 | M10: 2028719 | N10: 2024340 | O10: 2019672 | P10: 2015378 | Q10: 2009252 | R10: 2001748 | S10: 1990750 | T10: 1977094 | U10: 1959698 | V10: 1943238 | W10: 1926042 | X10: 1907179 | Y10: 1888644 | Z10: 1870451 | AA10: 1853919 | AB10: 1837151 | AC10: 1819452 | AD10: 1801975 | AE10: 1785262 | AF10: 1768869 | AG10: 1754337 | AH10: 1740662 | AI10: 1728315 | AJ10: 1717276 | AK10: 1707256 | AL10: 1699528 | AM10: 1693854 | AN10: 1690020 | AO10: 1687774
B11: 18-44 | C11: 1287491 | D11: 1268690 | E11: 1249671 | F11: 1232002 | G11: 1218195 | H11: 1208026 | I11: 1197218 | J11: 1181598 | K11: 1165360 | L11: 1149767 | M11: 1135904 | N11: 1122297 | O11: 1110757 | P11: 1100750 | Q11: 1089635 | R11: 1080020 | S11: 1070661 | T11: 1061514 | U11: 1052313 | V11: 1046195 | W11: 1042348 | X11: 1040166 | Y11: 1039739 | Z11: 1039219 | AA11: 1040316 | AB11: 1042729 | AC11: 1045688 | AD11: 1048086 | AE11: 1049155 | AF11: 1049138 | AG11: 1046765 | AH11: 1041249 | AI11: 1034708 | AJ11: 1028450 | AK11: 1024056 | AL11: 1020049 | AM11: 1017538 | AN11: 1014909 | AO11: 1012211
B12: 45-59/64 | C12: 758246 | D12: 766607 | E12: 776589 | F12: 788435 | G12: 800665 | H12: 817404 | I12: 837490 | J12: 855103 | K12: 870269 | L12: 882888 | M12: 892815 | N12: 902043 | O12: 908915 | P12: 914628 | Q12: 919617 | R12: 921728 | S12: 920089 | T12: 915580 | U12: 907385 | V12: 897043 | W12: 883694 | X12: 867013 | Y12: 848905 | Z12: 831232 | AA12: 813603 | AB12: 794422 | AC12: 773764 | AD12: 753889 | AE12: 736107 | AF12: 719731 | AG12: 707572 | AH12: 699413 | AI12: 693607 | AJ12: 688826 | AK12: 683200 | AL12: 679479 | AM12: 676316 | AN12: 675111 | AO12: 675563
B13: 60+/65+ | C13: 720908 | D13: 732720 | E13: 744065 | F13: 754270 | G13: 763226 | H13: 772694 | I13: 782294 | J13: 791367 | K13: 800185 | L13: 808504 | M13: 817459 | N13: 826844 | O13: 837113 | P13: 848123 | Q13: 860086 | R13: 871911 | S13: 884771 | T13: 898647 | U13: 913018 | V13: 927773 | W13: 943488 | X13: 960976 | Y13: 978250 | Z13: 994557 | AA13: 1008978 | AB13: 1023715 | AC13: 1039107 | AD13: 1054046 | AE13: 1067969 | AF13: 1081240 | AG13: 1092368 | AH13: 1102671 | AI13: 1111554 | AJ13: 1119436 | AK13: 1126157 | AL13: 1130784 | AM13: 1133785 | AN13: 1135193 | AO13: 1135199
B14: 0-2 | C14: 99461 | D14: 96942 | E14: 96243 | F14: 98789 | G14: 100066 | H14: 101513 | I14: 102704 | J14: 103093 | K14: 103164 | L14: 103077 | M14: 102682 | N14: 102094 | O14: 101380 | P14: 100753 | Q14: 100334 | R14: 100216 | S14: 100387 | T14: 100861 | U14: 101537 | V14: 102393 | W14: 103295 | X14: 104193 | Y14: 105018 | Z14: 105734 | AA14: 106301 | AB14: 106694 | AC14: 106916 | AD14: 106969 | AE14: 106804 | AF14: 106495 | AG14: 106030 | AH14: 105475 | AI14: 104804 | AJ14: 104107 | AK14: 103447 | AL14: 102850 | AM14: 102321 | AN14: 101928 | AO14: 101660
B15: 3-6 | C15: 154063 | D15: 151495 | E15: 146384 | F15: 139170 | G15: 134701 | H15: 134182 | I15: 135752 | J15: 139292 | K15: 140692 | L15: 141335 | M15: 141477 | N15: 141318 | O15: 141148 | P15: 140822 | Q15: 140220 | R15: 139485 | S15: 138724 | T15: 138160 | U15: 137916 | V15: 138028 | W15: 138534 | X15: 139343 | Y15: 140382 | Z15: 141566 | AA15: 142781 | AB15: 143954 | AC15: 144991 | AD15: 145859 | AE15: 146513 | AF15: 146930 | AG15: 147114 | AH15: 147022 | AI15: 146711 | AJ15: 146203 | AK15: 145480 | AL15: 144665 | AM15: 143787 | AN15: 142894 | AO15: 142043
B16: 7-14 | C16: 305059 | D16: 304567 | E16: 304683 | F16: 304392 | G16: 304723 | H16: 306055 | I16: 308572 | J16: 305560 | K16: 302526 | L16: 298369 | M16: 293014 | N16: 288335 | O16: 284608 | P16: 282943 | Q16: 282628 | R16: 285118 | S16: 286050 | T16: 286260 | U16: 285809 | V16: 285015 | W16: 284233 | X16: 283478 | Y16: 282783 | Z16: 282305 | AA16: 282173 | AB16: 282546 | AC16: 283438 | AD16: 284815 | AE16: 286589 | AF16: 288618 | AG16: 290718 | AH16: 292793 | AI16: 294652 | AJ16: 296209 | AK16: 297399 | AL16: 298119 | AM16: 298419 | AN16: 298277 | AO16: 297718
B17: 15-18 | C17: 136318 | D17: 142831 | E17: 149178 | F17: 154725 | G17: 156586 | H17: 156669 | I17: 155173 | J17: 153422 | K17: 153348 | L17: 154439 | M17: 158078 | N17: 160536 | O17: 161410 | P17: 158927 | Q17: 153715 | R17: 146325 | S17: 141544 | T17: 139385 | U17: 138961 | V17: 141559 | W17: 142578 | X17: 143052 | Y17: 143151 | Z17: 143047 | AA17: 142977 | AB17: 142742 | AC17: 142252 | AD17: 141639 | AE17: 140999 | AF17: 140553 | AG17: 140421 | AH17: 140615 | AI17: 141184 | AJ17: 142055 | AK17: 143133 | AL17: 144349 | AM17: 145560 | AN17: 146708 | AO17: 147705
B18: 19-24 | C18: 210905 | D18: 205365 | E18: 202352 | F18: 200196 | G18: 202007 | H18: 208995 | I18: 218067 | J18: 226210 | K18: 231466 | L18: 235924 | M18: 237080 | N18: 235670 | O18: 233633 | P18: 232876 | Q18: 235213 | R18: 236904 | S18: 238617 | T18: 237763 | U18: 235190 | V18: 228512 | W18: 221873 | X18: 216445 | Y18: 212592 | Z18: 210996 | AA18: 210609 | AB18: 213045 | AC18: 214083 | AD18: 214578 | AE18: 214564 | AF18: 214213 | AG18: 213776 | AH18: 213213 | AI18: 212494 | AJ18: 211826 | AK18: 211358 | AL18: 211241 | AM18: 211585 | AN18: 212392 | AO18: 213617
B19: 0-14 | C19: 558583 | D19: 553004 | E19: 547310 | F19: 542351 | G19: 539490 | H19: 541750 | I19: 547028 | J19: 547945 | K19: 546382 | L19: 542781 | M19: 537173 | N19: 531747 | O19: 527136 | P19: 524518 | Q19: 523182 | R19: 524819 | S19: 525161 | T19: 525281 | U19: 525262 | V19: 525436 | W19: 526062 | X19: 527014 | Y19: 528183 | Z19: 529605 | AA19: 531255 | AB19: 533194 | AC19: 535345 | AD19: 537643 | AE19: 539906 | AF19: 542043 | AG19: 543862 | AH19: 545290 | AI19: 546167 | AJ19: 546519 | AK19: 546326 | AL19: 545634 | AM19: 544527 | AN19: 543099 | AO19: 541421
B20: 15-64 | C20: 2258003 | D20: 2249796 | E20: 2243821 | F20: 2239384 | G20: 2235522 | H20: 2240305 | I20: 2247829 | J20: 2250032 | K20: 2249972 | L20: 2250722 | M20: 2252523 | N20: 2253175 | O20: 2251776 | P20: 2247144 | Q20: 2240602 | R20: 2230003 | S20: 2219657 | T20: 2207440 | U20: 2194768 | V20: 2180708 | W20: 2166423 | X20: 2150919 | Y20: 2134715 | Z20: 2117680 | AA20: 2101291 | AB20: 2082540 | AC20: 2061254 | AD20: 2040515 | AE20: 2020956 | AF20: 2003585 | AG20: 1987799 | AH20: 1972175 | AI20: 1957622 | AJ20: 1943572 | AK20: 1929489 | AL20: 1918156 | AM20: 1909186 | AN20: 1901842 | AO20: 1897196
... B22: 80+ | C22: 144463 | D22: 144847 | E22: 146676 | F22: 148587 | G22: 153142 | H22: 159873 | I22: 167662 | J22: 175443 | K22: 183718 | L22: 193125 | M22: 202409 | N22: 211772 | O22: 220664 | P22: 230152 | Q22: 238829 | R22: 247353 | S22: 255588 | T22: 262588 | U22: 268204 | V22: 272218 | W22: 275658 | X22: 278373 | Y22: 280993 | Z22: 283130 | AA22: 284790 | AB22: 286488 | AC22: 288296 | AD22: 290755 | AE22: 294102 | AF22: 297966 | AG22: 302794 | AH22: 308731 | AI22: 316396 | AJ22: 324890 | AK22: 334350 | AL22: 343771 | AM22: 354088 | AN22: 364855 | AO22: 375943
A23: Mężczyźni Males | B23: Ogółem Total | C23: 1663091 | D23: 1663512 | E23: 1664426 | F23: 1665597 | G23: 1666951 | H23: 1673185 | I23: 1681118 | J23: 1685428 | K23: 1687817 | L23: 1689399 | M23: 1690460 | N23: 1691106 | O23: 1691275 | P23: 1691340 | Q23: 1691278 | R23: 1691183 | S23: 1691121 | T23: 1690912 | U23: 1690756 | V23: 1690717 | W23: 1690804 | X23: 1690978 | Y23: 1691277 | Z23: 1691452 | AA23: 1691721 | AB23: 1692027 | AC23: 1692363 | AD23: 1692641 | AE23: 1692680 | AF23: 1692670 | AG23: 1692602 | AH23: 1692438 | AI23: 1692128 | AJ23: 1691776 | AK23: 1691112 | AL23: 1690362 | AM23: 1689582 | AN23: 1688769 | AO23: 1687951
B24: 0-17 | C24: 340122 | D24: 340173 | E24: 340443 | F24: 339801 | G24: 338023 | H24: 338677 | I24: 340292 | J24: 340650 | K24: 339919 | L24: 339276 | M24: 338037 | N24: 336301 | O24: 333784 | P24: 330425 | Q24: 327322 | R24: 325127 | S24: 323946 | T24: 323687 | U24: 324995 | V24: 325688 | W24: 326293 | X24: 326800 | Y24: 327360 | Z24: 328078 | AA24: 328901 | AB24: 329748 | AC24: 330618 | AD24: 331518 | AE24: 332440 | AF24: 333403 | AG24: 334347 | AH24: 335212 | AI24: 335948 | AJ24: 336513 | AK24: 336884 | AL24: 337007 | AM24: 336910 | AN24: 336599 | AO24: 336096
B25: 18-64 | C25: 1074233 | D25: 1067479 | E25: 1061544 | F25: 1057754 | G25: 1056303 | H25: 1057344 | I25: 1059429 | J25: 1059472 | K25: 1059040 | L25: 1058209 | M25: 1057481 | N25: 1056813 | O25: 1056583 | P25: 1056635 | Q25: 1056013 | R25: 1054294 | S25: 1050911 | T25: 1045612 | U25: 1038588 | V25: 1031518 | W25: 1024591 | X25: 1017408 | Y25: 1009815 | Z25: 1001970 | AA25: 994577 | AB25: 986158 | AC25: 976961 | AD25: 967791 | AE25: 959106 | AF25: 951341 | AG25: 944208 | AH25: 937139 | AI25: 930602 | AJ25: 923931 | AK25: 917391 | AL25: 912132 | AM25: 908247 | AN25: 905135 | AO25: 903360
B26: 18-44 | C26: 648684 | D26: 639259 | E26: 629390 | F26: 620550 | G26: 613657 | H26: 607378 | I26: 600880 | J26: 592534 | K26: 584340 | L26: 576653 | M26: 569943 | N26: 563524 | O26: 558318 | P26: 553608 | Q26: 548689 | R26: 544174 | S26: 540156 | T26: 536050 | U26: 531902 | V26: 529331 | W26: 527845 | X26: 527313 | Y26: 527547 | Z26: 527664 | AA26: 528626 | AB26: 530212 | AC26: 532124 | AD26: 533517 | AE26: 534350 | AF26: 534810 | AG26: 533974 | AH26: 531662 | AI26: 528628 | AJ26: 525483 | AK26: 523413 | AL26: 521589 | AM26: 520479 | AN26: 519281 | AO26: 518041
B27: 45-64 | C27: 425549 | D27: 428220 | E27: 432154 | F27: 437204 | G27: 442646 | H27: 449966 | I27: 458549 | J27: 466938 | K27: 474700 | L27: 481556 | M27: 487538 | N27: 493289 | O27: 498265 | P27: 503027 | Q27: 507324 | R27: 510120 | S27: 510755 | T27: 509562 | U27: 506686 | V27: 502187 | W27: 496746 | X27: 490095 | Y27: 482268 | Z27: 474306 | AA27: 465951 | AB27: 455946 | AC27: 444837 | AD27: 434274 | AE27: 424756 | AF27: 416531 | AG27: 410234 | AH27: 405477 | AI27: 401974 | AJ27: 398448 | AK27: 393978 | AL27: 390543 | AM27: 387768 | AN27: 385854 | AO27: 385319
B28: 65+ | C28: 248736 | D28: 255860 | E28: 262439 | F28: 268042 | G28: 272625 | H28: 277164 | I28: 281397 | J28: 285306 | K28: 288858 | L28: 291914 | M28: 294942 | N28: 297992 | O28: 300908 | P28: 304280 | Q28: 307943 | R28: 311762 | S28: 316264 | T28: 321613 | U28: 327173 | V28: 333511 | W28: 339920 | X28: 346770 | Y28: 354102 | Z28: 361404 | AA28: 368243 | AB28: 376121 | AC28: 384784 | AD28: 393332 | AE28: 401134 | AF28: 407926 | AG28: 414047 | AH28: 420087 | AI28: 425578 | AJ28: 431332 | AK28: 436837 | AL28: 441223 | AM28: 444425 | AN28: 447035 | AO28: 448495
B29: 0-2 | C29: 51034 | D29: 49748 | E29: 49503 | F29: 50867 | G29: 51522 | H29: 52276 | I29: 52882 | J29: 53080 | K29: 53116 | L29: 53080 | M29: 52887 | N29: 52584 | O29: 52217 | P29: 51898 | Q29: 51682 | R29: 51623 | S29: 51711 | T29: 51954 | U29: 52304 | V29: 52740 | W29: 53203 | X29: 53661 | Y29: 54086 | Z29: 54453 | AA29: 54750 | AB29: 54956 | AC29: 55075 | AD29: 55094 | AE29: 55009 | AF29: 54847 | AG29: 54608 | AH29: 54321 | AI29: 53985 | AJ29: 53626 | AK29: 53286 | AL29: 52977 | AM29: 52706 | AN29: 52496 | AO29: 52354
B30: 3-6 | C30: 79320 | D30: 78010 | E30: 75238 | F30: 71350 | G30: 69215 | H30: 68940 | I30: 69853 | J30: 71728 | K30: 72474 | L30: 72822 | M30: 72894 | N30: 72817 | O30: 72728 | P30: 72566 | Q30: 72268 | R30: 71891 | S30: 71501 | T30: 71214 | U30: 71091 | V30: 71150 | W30: 71415 | X30: 71827 | Y30: 72354 | Z30: 72957 | AA30: 73575 | AB30: 74177 | AC30: 74714 | AD30: 75173 | AE30: 75506 | AF30: 75723 | AG30: 75816 | AH30: 75758 | AI30: 75595 | AJ30: 75337 | AK30: 74967 | AL30: 74551 | AM30: 74102 | AN30: 73647 | AO30: 73214
B31: 7-14 | C31: 156801 | D31: 156779 | E31: 156957 | F31: 156785 | G31: 156820 | H31: 157564 | I31: 158726 | J31: 157100 | K31: 155503 | L31: 153373 | M31: 150609 | N31: 148112 | O31: 146377 | P31: 145537 | Q31: 145497 | R31: 146847 | S31: 147353 | T31: 147473 | U31: 147245 | V31: 146833 | W31: 146426 | X31: 146043 | Y31: 145694 | Z31: 145447 | AA31: 145380 | AB31: 145568 | AC31: 146020 | AD31: 146718 | AE31: 147620 | AF31: 148655 | AG31: 149730 | AH31: 150801 | AI31: 151747 | AJ31: 152548 | AK31: 153164 | AL31: 153539 | AM31: 153686 | AN31: 153617 | AO31: 153330
B32: 15-18 | C32: 69774 | D32: 72803 | E32: 76044 | F32: 79281 | G32: 80313 | H32: 80494 | I32: 79763 | J32: 78716 | K32: 78710 | L32: 79361 | M32: 81295 | N32: 82657 | O32: 82942 | P32: 81684 | Q32: 78869 | R32: 74912 | S32: 72604 | T32: 71492 | U32: 71394 | V32: 72799 | W32: 73355 | X32: 73612 | Y32: 73662 | Z32: 73610 | AA32: 73565 | AB32: 73444 | AC32: 73196 | AD32: 72878 | AE32: 72558 | AF32: 72330 | AG32: 72264 | AH32: 72364 | AI32: 72652 | AJ32: 73094 | AK32: 73640 | AL32: 74263 | AM32: 74888 | AN32: 75478 | AO32: 75992
B33: 19-24 | C33: 106829 | D33: 104486 | E33: 103154 | F33: 101975 | G33: 103001 | H33: 106318 | I33: 110849 | J33: 115071 | K33: 117857 | L33: 120352 | M33: 121123 | N33: 120753 | O33: 119846 | P33: 119319 | Q33: 120580 | R33: 121665 | S33: 122433 | T33: 121991 | U33: 120558 | V33: 117103 | W33: 113676 | X33: 110797 | Y33: 108991 | Z33: 108187 | AA33: 108125 | AB33: 109441 | AC33: 110000 | AD33: 110272 | AE33: 110270 | AF33: 110090 | AG33: 109856 | AH33: 109566 | AI33: 109212 | AJ33: 108871 | AK33: 108637 | AL33: 108572 | AM33: 108754 | AN33: 109169 | AO33: 109785
B34: 0-14 | C34: 287155 | D34: 284537 | E34: 281698 | F34: 279002 | G34: 277557 | H34: 278780 | I34: 281461 | J34: 281908 | K34: 281093 | L34: 279275 | M34: 276390 | N34: 273513 | O34: 271322 | P34: 270001 | Q34: 269447 | R34: 270361 | S34: 270565 | T34: 270641 | U34: 270640 | V34: 270723 | W34: 271044 | X34: 271531 | Y34: 272134 | Z34: 272857 | AA34: 273705 | AB34: 274701 | AC34: 275809 | AD34: 276985 | AE34: 278135 | AF34: 279225 | AG34: 280154 | AH34: 280880 | AI34: 281327 | AJ34: 281511 | AK34: 281417 | AL34: 281067 | AM34: 280494 | AN34: 279760 | AO34: 278898
B35: 15-64 | C35: 1127200 | D35: 1123115 | E35: 1120289 | F35: 1118553 | G35: 1116769 | H35: 1117241 | I35: 1118260 | J35: 1118214 | K35: 1117866 | L35: 1118210 | M35: 1119128 | N35: 1119601 | O35: 1119045 | P35: 1117059 | Q35: 1113888 | R35: 1109060 | S35: 1104292 | T35: 1098658 | U35: 1092943 | V35: 1086483 | W35: 1079840 | X35: 1072677 | Y35: 1065041 | Z35: 1057191 | AA35: 1049773 | AB35: 1041205 | AC35: 1031770 | AD35: 1022324 | AE35: 1013411 | AF35: 1005519 | AG35: 998401 | AH35: 991471 | AI35: 985223 | AJ35: 978933 | AK35: 972858 | AL35: 968072 | AM35: 964663 | AN35: 961974 | AO35: 960558
... B37: 80+ | C37: 46306 | D37: 46699 | E37: 47458 | F37: 48377 | G37: 50153 | H37: 52829 | I37: 55909 | J37: 58891 | K37: 62237 | L37: 65993 | M37: 69711 | N37: 73483 | O37: 77101 | P37: 80915 | Q37: 84367 | R37: 87850 | S37: 91287 | T37: 94194 | U37: 96467 | V37: 98126 | W37: 99666 | X37: 101067 | Y37: 102398 | Z37: 103536 | AA37: 104475 | AB37: 105516 | AC37: 106685 | AD37: 107997 | AE37: 109603 | AF37: 111555 | AG37: 113738 | AH37: 116474 | AI37: 119946 | AJ37: 123673 | AK37: 127874 | AL37: 132116 | AM37: 136667 | AN37: 141565 | AO37: 146494
A38: Kobiety Females | B38: Ogółem Total | C38: 1765923 | D38: 1766849 | E38: 1768272 | F38: 1770022 | G38: 1772142 | H38: 1783165 | I38: 1797670 | J38: 1805110 | K38: 1808837 | L38: 1811246 | M38: 1812762 | N38: 1813720 | O38: 1814177 | P38: 1814298 | Q38: 1814323 | R38: 1814120 | S38: 1813711 | T38: 1813393 | U38: 1812937 | V38: 1812575 | W38: 1812141 | X38: 1811576 | Y38: 1811119 | Z38: 1810479 | AA38: 1809704 | AB38: 1809004 | AC38: 1808062 | AD38: 1807000 | AE38: 1805982 | AF38: 1804749 | AG38: 1803260 | AH38: 1801769 | AI38: 1800056 | AJ38: 1798351 | AK38: 1796435 | AL38: 1794326 | AM38: 1792236 | AN38: 1790014 | AO38: 1787609
B39: 0-17 | C39: 322247 | D39: 322171 | E39: 321930 | F39: 321111 | G39: 318984 | H39: 319549 | I39: 321494 | J39: 321820 | K39: 320921 | L39: 320210 | M39: 319007 | N39: 317341 | O39: 314883 | P39: 311712 | Q39: 308941 | R39: 306517 | S39: 305365 | T39: 304877 | U39: 305982 | V39: 306593 | W39: 307122 | X39: 307599 | Y39: 308142 | Z39: 308845 | AA39: 309627 | AB39: 310417 | AC39: 311248 | AD39: 312102 | AE39: 312991 | AF39: 313907 | AG39: 314810 | AH39: 315662 | AI39: 316367 | AJ39: 316902 | AK39: 317250 | AL39: 317369 | AM39: 317269 | AN39: 316971 | AO39: 316491
B40: 18-59 | C40: 971504 | D40: 967818 | E40: 964716 | F40: 962683 | G40: 962557 | H40: 968086 | I40: 975279 | J40: 977229 | K40: 976589 | L40: 974446 | M40: 971238 | N40: 967527 | O40: 963089 | P40: 958743 | Q40: 953239 | R40: 947454 | S40: 939839 | T40: 931482 | U40: 921110 | V40: 911720 | W40: 901451 | X40: 889771 | Y40: 878829 | Z40: 868481 | AA40: 859342 | AB40: 850993 | AC40: 842491 | AD40: 834184 | AE40: 826156 | AF40: 817528 | AG40: 810129 | AH40: 803523 | AI40: 797713 | AJ40: 793345 | AK40: 789865 | AL40: 787396 | AM40: 785607 | AN40: 784885 | AO40: 784414
B41: 18-44 | C41: 638807 | D41: 629431 | E41: 620281 | F41: 611452 | G41: 604538 | H41: 600648 | I41: 596338 | J41: 589064 | K41: 581020 | L41: 573114 | M41: 565961 | N41: 558773 | O41: 552439 | P41: 547142 | Q41: 540946 | R41: 535846 | S41: 530505 | T41: 525464 | U41: 520411 | V41: 516864 | W41: 514503 | X41: 512853 | Y41: 512192 | Z41: 511555 | AA41: 511690 | AB41: 512517 | AC41: 513564 | AD41: 514569 | AE41: 514805 | AF41: 514328 | AG41: 512791 | AH41: 509587 | AI41: 506080 | AJ41: 502967 | AK41: 500643 | AL41: 498460 | AM41: 497059 | AN41: 495628 | AO41: 494170
B42: 45-59 | C42: 332697 | D42: 338387 | E42: 344435 | F42: 351231 | G42: 358019 | H42: 367438 | I42: 378941 | J42: 388165 | K42: 395569 | L42: 401332 | M42: 405277 | N42: 408754 | O42: 410650 | P42: 411601 | Q42: 412293 | R42: 411608 | S42: 409334 | T42: 406018 | U42: 400699 | V42: 394856 | W42: 386948 | X42: 376918 | Y42: 366637 | Z42: 356926 | AA42: 347652 | AB42: 338476 | AC42: 328927 | AD42: 319615 | AE42: 311351 | AF42: 303200 | AG42: 297338 | AH42: 293936 | AI42: 291633 | AJ42: 290378 | AK42: 289222 | AL42: 288936 | AM42: 288548 | AN42: 289257 | AO42: 290244
...

Sheet Tabl. 4
B1: TABL. 4. RUCH NATURALNY I MIGRACYJNY LUDNOŚCI
A2: Powrót do spisu tablic | C2: VITAL STATISTICS
A3: Return to the list of tables
A4: małopolskie
A5: Rok Year | B5: Ruch naturalny Natural movement | D5: Migracje wewnętrzne na pobyt stały Internal migration for permanent residence | F5: Migracje zagraniczne na pobyt stały International migration for pemanent residence
B6: Urodzenia Births | C6: Zgony Deaths | D6: Napływ Inflow | E6: Odpływ Outflow | F6: Immigracja Imigration | G6: Emigracja Emigration
A7: 2023 | B7: 32163 | C7: 35846 | D7: 32439 | E7: 29606 | F7: 3286 | G7: 1093
A8: 2024 | B8: 32711 | C8: 35604 | D8: 31937 | E8: 29280 | F8: 3643 | G8: 1070
A9: 2025 | B9: 33106 | C9: 35732 | D9: 31431 | E9: 29016 | F9: 4158 | G9: 1026
A10: 2026 | B10: 33361 | C10: 35822 | D10: 30938 | E10: 28780 | F10: 4792 | G10: 1015
A11: 2027 | B11: 33515 | C11: 36138 | D11: 30524 | E11: 28531 | F11: 18873 | G11: 986
A12: 2028 | B12: 33756 | C12: 36409 | D12: 30285 | E12: 28482 | F12: 24272 | G12: 984
A13: 2029 | B13: 33971 | C13: 36785 | D13: 30217 | E13: 28489 | F13: 13797 | G13: 961
A14: 2030 | B14: 33940 | C14: 37102 | D14: 30033 | E14: 28375 | F14: 8571 | G14: 951
A15: 2031 | B15: 33838 | C15: 37320 | D15: 29873 | E15: 28268 | F15: 6807 | G15: 939
